Workbook

Sheet START HERE
A1: Cells contained in this worksheet may contain cells with dropdown lists as well as autopopulated formulas.
A2: HECVAT™ Solution Provider Response - Start Here | F2: ='Auto Responses'!$A$36 -> Version 4.04
A3: Date Completed | C3: 45933
A4: Instructions for Solution Providers
A5: =HLOOKUP($A$4,'Auto Responses'!$D$2:$D$8,2,0)&"" -> 1. Complete the "Start Here" tab and review the "Required Questions" guidance to find the other sections are required for your product or service.
A6: =HLOOKUP($A$4,'Auto Responses'!$D$2:$D$8,3,0)&"" -> 2. Complete the "Organization" tab and the applicable questions in each of the next 5 tabs (Product through Privacy) that apply, based on your answers to the "Required Questions."
A7: =HLOOKUP($A$4,'Auto Responses'!$D$2:$D$8,4,0)&"" -> 3. Guidance in column E may change based on your answers to prompt details in "Additional Information." If leaving an answer blank, you must also state why in "Additional Information".
A8: =HLOOKUP($A$4,'Auto Responses'!$D$2:$D$8,5,0)&"" -> 4. DO NOT complete any fields in the "Evaluation" sheets or the "Analyst Notes" column.
A9: =HLOOKUP($A$4,'Auto Responses'!$D$2:$D$8,6,0)&"" -> 5. Return the completed file to institutions.
A10: =HLOOKUP($A$4,'Auto Responses'!$D$2:$D$8,7,0)&"" -> * Denotes critical questions. Critical questions are those deemed most important to institutions by higher education volunteers.
A11: =HLOOKUP($A$4,'Auto Responses'!$D$2:$D$9,8,0)&"" -> For full instructions, please visit educause.edu/HECVAT
A12: =VLOOKUP(LEFT($A13,4),'Auto Responses'!$N$4:$O$38,2,0)&"" -> General Information
A13: GNRL-01 | B13: =VLOOKUP($A13,Questions!$A$2:$X$333,2,0)&"" -> Solution Provider Name | C13: Coursedog
A14: GNRL-02 | B14: =VLOOKUP($A14,Questions!$A$2:$X$333,2,0)&"" -> Solution Name | C14: Coursedog
A15: GNRL-03 | B15: =VLOOKUP($A15,Questions!$A$2:$X$333,2,0)&"" -> Solution Description | C15: Coursedog is a SaaS platform designed to streamline curriculum, catalog, and scheduling management for higher education institutions, offering intuitive tools, insightful analytics, and seamless integration without requiring IT involvement.
A16: GNRL-04 | B16: =VLOOKUP($A16,Questions!$A$2:$X$333,2,0)&"" -> Solution Provider Contact Name
A17: GNRL-05 | B17: =VLOOKUP($A17,Questions!$A$2:$X$333,2,0)&"" -> Solution Provider Contact Title
A18: GNRL-06 | B18: =VLOOKUP($A18,Questions!$A$2:$X$333,2,0)&"" -> Solution Provider Contact Email | C18: contracts@coursedog.com
A19: GNRL-07 | B19: =VLOOKUP($A19,Questions!$A$2:$X$333,2,0)&"" -> Solution Provider Contact Phone Number | C19: (913) 565-2513
A20: GNRL-08 | B20: =VLOOKUP($A20,Questions!$A$2:$X$333,2,0)&"" -> Country of Company Headquarters | C20: United States
A21: GNRL-09 | B21: =VLOOKUP($A21,Questions!$A$2:$X$333,2,0)&"" -> Employee Work Locations (all) | C21: New York, various remote locations
A22: =VLOOKUP(LEFT($A23,4),'Auto Responses'!$N$4:$O$38,2,0)&"" -> Company Information | C22: Answer | D22: Additional Information | E22: Guidance | F22: Analyst Notes
A23: COMP-01 | B23: =VLOOKUP($A23,Questions!$A$2:$X$333,2,0)&"" -> Do you have a dedicated software and system development team(s) (e.g., customer support, implementation, product management, etc.)?* | C23: Yes | D23: Coursedog has a dedicated teams including Customer Success, Product Management, Customer Support, and Engineering. | E23: =IF($C23="Yes",VLOOKUP($A23,Questions!$A$2:$X$333,17,0)&"",IF($C23="No",VLOOKUP($A23,Questions!$A$2:$X$333,16,0)&"",VLOOKUP($A23,Questions!$A$2:$X$333,15,0)&"")) -> Describe the structure and size of your software and system development teams. (e.g., customer support, implementation, product management, etc.). | F23: =VLOOKUP($A23,'Institution Evaluation'!$A$56:$F$346,6,0)&""
A24: COMP-02 | B24: =VLOOKUP($A24,Questions!$A$2:$X$333,2,0)&"" -> Describe your organization’s business background and ownership structure, including all parent and subsidiary relationships. | D24: Coursedog, a leading Academic Operations Platform for higher education, has received a $90 million strategic growth investment from JMI Equity (“JMI”), a growth equity firm focused on investing in leading software companies. A three-time Forbes Top 500 Startup Employer, Coursedog is the leading Academic Operations Platform for Higher Education institutions. Coursedog was founded by Forbes 30 Under 30 members Justin Wenig and Nicholas Diao in 2018. JMI Equity is a growth equity firm focused on investing in leading software companies. For over three decades, JMI has partnered with exceptional founders, entrepreneurs, and management teams at high-growth software companies to provide flexible capital, industry expertise, and operational support to build businesses of enduring value. To date, JMI has invested in over 180 software businesses in North America and Europe and completed over 115 exits. Today, the Firm’s portfolio of industry-leading cloud software companies represents $8 billion in combined revenue, $65 billion in aggregate enterprise value, and over 34,000 jobs. | F24: =VLOOKUP($A24,'Institution Evaluation'!$A$56:$F$346,6,0)&""
A25: COMP-03 | B25: =VLOOKUP($A25,Questions!$A$2:$X$333,2,0)&"" -> Have you operated without unplanned disruptions to this solution in the past 12 months? | C25: No | E25: =IF($C25="Yes",VLOOKUP($A25,Questions!$A$2:$X$333,17,0)&"",IF($C25="No",VLOOKUP($A25,Questions!$A$2:$X$333,16,0)&"",VLOOKUP($A25,Questions!$A$2:$X$333,15,0)&"")) -> Provide a detailed summary of the unplanned disruption. | F25: =VLOOKUP($A25,'Institution Evaluation'!$A$56:$F$346,6,0)&""
A26: COMP-04 | B26: =VLOOKUP($A26,Questions!$A$2:$X$333,2,0)&"" -> Do you have a dedicated information security staff or office? | C26: Yes | D26: Roughly half of Coursedog is dedicated to R&D. This includes a Product Management and engineering teams. The Engineering team is led by a CTO and has a full time security officer. Each Engineer adheres to best practices set forth by the organization. Coursedog leverages external third parties for vulnerability scans and hosting (i.e. AWS). | E26: =IF($C26="Yes",VLOOKUP($A26,Questions!$A$2:$X$333,17,0)&"",IF($C26="No",VLOOKUP($A26,Questions!$A$2:$X$333,16,0)&"",VLOOKUP($A26,Questions!$A$2:$X$333,15,0)&"")) -> Describe your information security office, including size, talents, resources, etc. | F26: =VLOOKUP($A26,'Institution Evaluation'!$A$56:$F$346,6,0)&""
A27: COMP-05 | B27: =VLOOKUP($A27,Questions!$A$2:$X$333,2,0)&"" -> Use this area to share information about your environment that will assist those who are assessing your company's data security program. | D27: See our Coursedog Security Overview | F27: =VLOOKUP($A27,'Institution Evaluation'!$A$56:$F$346,6,0)&"" | G27: End Table Data
A28: =VLOOKUP(LEFT($A29,4),'Auto Responses'!$N$4:$O$38,2,0)&"" -> Required Questions | C28: Answer | D28: Additional Information | E28: Guidance | F28: Analyst Notes
A29: REQU-01 | B29: =VLOOKUP($A29,Questions!$A$2:$X$333,2,0)&"" -> Are you offering either a product or platform, as opposed to only offering a service | C29: Yes | D29: Coursedog is a SaaS platform designed to streamline curriculum, catalog, and scheduling management for higher education institutions, offering intuitive tools, insightful analytics, and seamless integration without requiring IT involvement. | E29: =IF($C29="Yes",VLOOKUP($A29,Questions!$A$2:$X$333,17,0)&"",IF($C29="No",VLOOKUP($A29,Questions!$A$2:$X$333,16,0)&"",VLOOKUP($A29,Questions!$A$2:$X$333,15,0)&"")) -> DO complete the Product and Infrastructure worksheets | F29: =VLOOKUP($A29,'Institution Evaluation'!$A$56:$F$346,6,0)&""
A30: REQU-02 | B30: =VLOOKUP($A30,Questions!$A$2:$X$333,2,0)&"" -> Does your product or service have an interface? | C30: Yes | D30: Coursedog provides a UI for all of its products with the platform | E30: =IF($C30="Yes",VLOOKUP($A30,Questions!$A$2:$X$333,17,0)&"",IF($C30="No",VLOOKUP($A30,Questions!$A$2:$X$333,16,0)&"",VLOOKUP($A30,Questions!$A$2:$X$333,15,0)&"")) -> DO complete the IT Accessibility worksheet. | F30: =VLOOKUP($A30,'Institution Evaluation'!$A$56:$F$346,6,0)&""
A31: REQU-03 | B31: =VLOOKUP($A31,Questions!$A$2:$X$333,2,0)&"" -> Are you providing consulting services? | C31: Yes | D31: Coursedog's professional services team, led by a project manager/subject matter expert, can work with your team for intensive business process consulting. | E31: =IF($C31="Yes",VLOOKUP($A31,Questions!$A$2:$X$333,17,0)&"",IF($C31="No",VLOOKUP($A31,Questions!$A$2:$X$333,16,0)&"",VLOOKUP($A31,Questions!$A$2:$X$333,15,0)&"")) -> DO complete the Consulting section in the Case-Specific worksheet | F31: =VLOOKUP($A31,'Institution Evaluation'!$A$56:$F$346,6,0)&""
A32: REQU-04 | B32: =VLOOKUP($A32,Questions!$A$2:$X$333,2,0)&"" -> Does your solution have AI features, or are there plans to implement AI features in the next 12 months? | C32: Yes | D32: Coursedog has implemented AI features including OpenAI integration for chat completions and embeddings, AI Hub product for controlling AI operations, merge error solutions with AI-powered recommendations, and an agentic chat assistant called "Cassie". | E32: =IF($C32="Yes",VLOOKUP($A32,Questions!$A$2:$X$333,17,0)&"",IF($C32="No",VLOOKUP($A32,Questions!$A$2:$X$333,16,0)&"",VLOOKUP($A32,Questions!$A$2:$X$333,15,0)&"")) -> DO complete the Artificial Intelligence (AI) worksheet | F32: =VLOOKUP($A32,'Institution Evaluation'!$A$56:$F$346,6,0)&""
A33: REQU-05 | B33: =VLOOKUP($A33,Questions!$A$2:$X$333,2,0)&"" -> Does your solution process protected health information (PHI) or any data covered by the Health Insurance Portability and Accountability Act (HIPAA)? | C33: No | E33: =IF($C33="Yes",VLOOKUP($A33,Questions!$A$2:$X$333,17,0)&"",IF($C33="No",VLOOKUP($A33,Questions!$A$2:$X$333,16,0)&"",VLOOKUP($A33,Questions!$A$2:$X$333,15,0)&"")) -> DO NOT complete the HIPAA section in the Case-Specific worksheet | F33: =VLOOKUP($A33,'Institution Evaluation'!$A$56:$F$346,6,0)&""
A34: REQU-06 | B34: =VLOOKUP($A34,Questions!$A$2:$X$333,2,0)&"" -> Is the solution designed to process, store, or transmit credit card information? | C34: No | E34: =IF($C34="Yes",VLOOKUP($A34,Questions!$A$2:$X$333,17,0)&"",IF($C34="No",VLOOKUP($A34,Questions!$A$2:$X$333,16,0)&"",VLOOKUP($A34,Questions!$A$2:$X$333,15,0)&"")) -> DO NOT complete the PCI-DSS section in the Case-Specific worksheet | F34: =VLOOKUP($A34,'Institution Evaluation'!$A$56:$F$346,6,0)&""
A35: REQU-07 | B35: =VLOOKUP($A35,Questions!$A$2:$X$333,2,0)&"" -> Does operating your solution require the institution to operate a physical or virtual appliance in their own environment or to provide inbound firewall exceptions to allow your employees to remotely administer systems in the institution's environment? | C35: No | E35: =IF($C35="Yes",VLOOKUP($A35,Questions!$A$2:$X$333,17,0)&"",IF($C35="No",VLOOKUP($A35,Questions!$A$2:$X$333,16,0)&"",VLOOKUP($A35,Questions!$A$2:$X$333,15,0)&"")) -> DO NOT complete the On-Prem section in the Case-Specific worksheet | F35: =VLOOKUP($A35,'Institution Evaluation'!$A$56:$F$346,6,0)&""
A36: REQU-08 | B36: =VLOOKUP($A36,Questions!$A$2:$X$333,2,0)&"" -> Does your solution have access to personal or institutional data? | C36: No | E36: =IF($C36="Yes",VLOOKUP($A36,Questions!$A$2:$X$333,17,0)&"",IF($C36="No",VLOOKUP($A36,Questions!$A$2:$X$333,16,0)&"",VLOOKUP($A36,Questions!$A$2:$X$333,15,0)&"")) -> DO NOT complete the Privacy tab | F36: =VLOOKUP($A36,'Institution Evaluation'!$A$56:$F$346,6,0)&"" | G36: End Table Data
A37: Note: The "Organization" tab is required for ALL products and services.
A38: Copyright © 2025 EDUCAUSE

Sheet Organization
A1: Cells contained in this worksheet may contain cells with dropdown lists as well as autopopulated formulas.
A2: HECVAT Solution Provider Response - Organization | F2: ='Auto Responses'!$A$36 -> Version 4.04
A3: Date Completed | C3: ='START HERE'!$C$3 -> 45933
A4: Instructions for Solution Providers
A5: =HLOOKUP($A$4,'Auto Responses'!$D$2:$D$8,2,0)&"" -> 1. Complete the "Start Here" tab and review the "Required Questions" guidance to find the other sections are required for your product or service.
A6: =HLOOKUP($A$4,'Auto Responses'!$D$2:$D$8,3,0)&"" -> 2. Complete the "Organization" tab and the applicable questions in each of the next 5 tabs (Product through Privacy) that apply, based on your answers to the "Required Questions."
A7: =HLOOKUP($A$4,'Auto Responses'!$D$2:$D$8,4,0)&"" -> 3. Guidance in column E may change based on your answers to prompt details in "Additional Information." If leaving an answer blank, you must also state why in "Additional Information".
A8: =HLOOKUP($A$4,'Auto Responses'!$D$2:$D$8,5,0)&"" -> 4. DO NOT complete any fields in the "Evaluation" sheets or the "Analyst Notes" column.
A9: =HLOOKUP($A$4,'Auto Responses'!$D$2:$D$8,6,0)&"" -> 5. Return the completed file to institutions.
A10: =HLOOKUP($A$4,'Auto Responses'!$D$2:$D$8,7,0)&"" -> * Denotes critical questions. Critical questions are those deemed most important to institutions by higher education volunteers.
A11: =HLOOKUP($A$4,'Auto Responses'!$D$2:$D$9,8,0)&"" -> For full instructions, please visit educause.edu/HECVAT
A12: =VLOOKUP(LEFT($A13,4),'Auto Responses'!$N$4:$O$38,2,0)&"" -> General Information | C12: Answer
A13: GNRL-01 | B13: =VLOOKUP($A13,Questions!$A$2:$X$333,2,0)&"" -> Solution Provider Name | C13: =VLOOKUP($A13,'START HERE'!$A$13:$C$21,3,0)&"" -> Coursedog
A14: GNRL-02 | B14: =VLOOKUP($A14,Questions!$A$2:$X$333,2,0)&"" -> Solution Name | C14: =VLOOKUP($A14,'START HERE'!$A$13:$C$21,3,0)&"" -> Coursedog
A15: GNRL-03 | B15: =VLOOKUP($A15,Questions!$A$2:$X$333,2,0)&"" -> Solution Description | C15: =VLOOKUP($A15,'START HERE'!$A$13:$C$21,3,0)&"" -> Coursedog is a SaaS platform designed to streamline curriculum, catalog, and scheduling management for higher education institutions, offering intuitive tools, insightful analytics, and seamless integration without requiring IT involvement.
A16: GNRL-04 | B16: =VLOOKUP($A16,Questions!$A$2:$X$333,2,0)&"" -> Solution Provider Contact Name | C16: =VLOOKUP($A16,'START HERE'!$A$13:$C$21,3,0)&""
A17: GNRL-05 | B17: =VLOOKUP($A17,Questions!$A$2:$X$333,2,0)&"" -> Solution Provider Contact Title | C17: =VLOOKUP($A17,'START HERE'!$A$13:$C$21,3,0)&""
A18: GNRL-06 | B18: =VLOOKUP($A18,Questions!$A$2:$X$333,2,0)&"" -> Solution Provider Contact Email | C18: =VLOOKUP($A18,'START HERE'!$A$13:$C$21,3,0)&"" -> contracts@coursedog.com
A19: GNRL-07 | B19: =VLOOKUP($A19,Questions!$A$2:$X$333,2,0)&"" -> Solution Provider Contact Phone Number | C19: =VLOOKUP($A19,'START HERE'!$A$13:$C$21,3,0)&"" -> (913) 565-2513
A20: GNRL-08 | B20: =VLOOKUP($A20,Questions!$A$2:$X$333,2,0)&"" -> Country of Company Headquarters | C20: =VLOOKUP($A20,'START HERE'!$A$13:$C$21,3,0)&"" -> United States
A21: =VLOOKUP(LEFT($A22,4),'Auto Responses'!$N$4:$O$38,2,0)&"" -> Documentation | C21: Answer | D21: Additional Information | E21: Guidance | F21: Analyst Notes
A22: DOCU-01 | B22: =VLOOKUP($A22,Questions!$A$2:$X$333,2,0) -> Do you have a well-documented business continuity plan (BCP), with a clear owner, that is tested annually?* | C22: Yes | D22: See our Coursedog Business Continutity and AWS disaster recovery procedure | F22: =VLOOKUP($A22,'Institution Evaluation'!$A$56:$F$346,6,0)&""
A23: DOCU-02 | B23: =VLOOKUP($A23,Questions!$A$2:$X$333,2,0) -> Do you have a well-documented disaster recovery plan (DRP), with a clear owner, that is tested annually?* | C23: Yes | D23: See AWS disaster recovery procedure | E23: =IF($C23="Yes",VLOOKUP($A23,Questions!$A$2:$X$333,17,0)&"",IF($C23="No",VLOOKUP($A23,Questions!$A$2:$X$333,16,0)&"",VLOOKUP($A23,Questions!$A$2:$X$333,15,0)&"")) | F23: =VLOOKUP($A23,'Institution Evaluation'!$A$56:$F$346,6,0)&""
A24: DOCU-03 | B24: =VLOOKUP($A24,Questions!$A$2:$X$333,2,0) -> Have you undergone a SSAE 18/SOC 2 audit? | C24: No | D24: SOCII compliance has been deferred to a later date. This decision is based on the fact that Coursedog does not store or process any personally identifiable information (PII), and none of our 300+ current customers require SOCII compliance at this time. For your reference, you can review details about SOCII and related compliance frameworks as they apply to our infrastructure provider, AWS, here. | E24: =IF($C24="Yes",VLOOKUP($A24,Questions!$A$2:$X$333,17,0)&"",IF($C24="No",VLOOKUP($A24,Questions!$A$2:$X$333,16,0)&"",VLOOKUP($A24,Questions!$A$2:$X$333,15,0)&"")) -> Describe any plans to undergo a SSAE 18 audit. | F24: =VLOOKUP($A24,'Institution Evaluation'!$A$56:$F$346,6,0)&""
A25: DOCU-04 | B25: =VLOOKUP($A25,Questions!$A$2:$X$333,2,0) -> Do you conform with a specific industry standard security framework (e.g., NIST Cybersecurity Framework, CIS Controls, ISO 27001, etc.)? | C25: No | D25: Coursedog has not obtained NIST SP 800-171 or CMMC Level 2 compliance certifications. However, Coursedog follows industry best practices for data security. Coursedog is in the process of obtaining the official ISO27001 certification. | E25: =IF($C25="Yes",VLOOKUP($A25,Questions!$A$2:$X$333,17,0)&"",IF($C25="No",VLOOKUP($A25,Questions!$A$2:$X$333,16,0)&"",VLOOKUP($A25,Questions!$A$2:$X$333,15,0)&"")) -> Describe any plans to conform to an industry standard security framework. | F25: =VLOOKUP($A25,'Institution Evaluation'!$A$56:$F$346,6,0)&""
A26: DOCU-05 | B26: =VLOOKUP($A26,Questions!$A$2:$X$333,2,0) -> Can you provide overall system and/or application architecture diagrams, including a full description of the data flow for all components of the system? | C26: Yes | D26: See our Coursedog Application Architecture for more detailed information. | E26: =IF($C26="Yes",VLOOKUP($A26,Questions!$A$2:$X$333,17,0)&"",IF($C26="No",VLOOKUP($A26,Questions!$A$2:$X$333,16,0)&"",VLOOKUP($A26,Questions!$A$2:$X$333,15,0)&"")) -> Provide your diagrams (or a valid link to it) upon submission. | F26: =VLOOKUP($A26,'Institution Evaluation'!$A$56:$F$346,6,0)&""
A27: DOCU-06 | B27: =VLOOKUP($A27,Questions!$A$2:$X$333,2,0) -> Does your organization have a data privacy policy? | C27: Yes | D27: See our Privacy Policy | E27: =IF($C27="Yes",VLOOKUP($A27,Questions!$A$2:$X$333,17,0)&"",IF($C27="No",VLOOKUP($A27,Questions!$A$2:$X$333,16,0)&"",VLOOKUP($A27,Questions!$A$2:$X$333,15,0)&"")) -> Provide your data privacy document (or a valid link to it) upon submission. | F27: =VLOOKUP($A27,'Institution Evaluation'!$A$56:$F$346,6,0)&""
A28: DOCU-07 | B28: =VLOOKUP($A28,Questions!$A$2:$X$333,2,0) -> Do you have a documented, and currently implemented, employee onboarding and offboarding policy? | C28: Yes | D28: The Coursedog onboarding document contains sensitive information and therefore is not available publically. | E28: =IF($C28="Yes",VLOOKUP($A28,Questions!$A$2:$X$333,17,0)&"",IF($C28="No",VLOOKUP($A28,Questions!$A$2:$X$333,16,0)&"",VLOOKUP($A28,Questions!$A$2:$X$333,15,0)&"")) -> Provide a reference to your employee onboarding and offboarding policy and supporting documentation or submit it along with this fully populated HECVAT. | F28: =VLOOKUP($A28,'Institution Evaluation'!$A$56:$F$346,6,0)&"" | G28: End Table Data
A29: =VLOOKUP(LEFT($A30,4),'Auto Responses'!$N$4:$O$38,2,0)&"" -> Assessment of Third Parties | C29: Answer | D29: Additional Information | E29: Guidance | F29: Analyst Notes
A30: THRD-01 | B30: =VLOOKUP($A30,Questions!$A$2:$X$333,2,0) -> Do you perform security assessments of third-party companies with which you share data (e.g., hosting providers, cloud services, PaaS, IaaS, SaaS)?* | C30: Yes | D30: Coursedog assess third party vendors based on data security (use of encryption and data security during processing transmission and storage, and data recoverable procedures) and network security (review of network architecture and security configurations, Anti-virus controls, penetration testing, security monitoring capabilities). | F30: =VLOOKUP($A30,'Institution Evaluation'!$A$56:$F$346,6,0)&""
A31: THRD-02 | B31: =VLOOKUP($A31,Questions!$A$2:$X$333,2,0) -> Do you have contractual language in place with third parties governing access to institutional data?* | C31: Yes | D31: Coursedog assess third party vendors based on data security (use of encryption and data security during processing transmission and storage, and data recoverable procedures) and network security (review of network architecture and security configurations, Anti-virus controls, penetration testing, security monitoring capabilities). | F31: =VLOOKUP($A31,'Institution Evaluation'!$A$56:$F$346,6,0)&""
A32: THRD-03 | B32: =VLOOKUP($A32,Questions!$A$2:$X$333,2,0) -> Do the contracts in place with these third parties address liability in the event of a data breach?* | C32: Yes | D32: For each of these vendors, we use their standard SaaS agreements and each of them have guardrails in place the address liabiliity in case of a data breach. | F32: =VLOOKUP($A32,'Institution Evaluation'!$A$56:$F$346,6,0)&""
A33: THRD-04 | B33: =VLOOKUP($A33,Questions!$A$2:$X$333,2,0) -> Do you have an implemented third-party management strategy?* | C33: Yes | D33: See Coursedog Architecture for more information. | E33: =IF($C33="Yes",VLOOKUP($A33,Questions!$A$2:$X$333,17,0)&"",IF($C33="No",VLOOKUP($A33,Questions!$A$2:$X$333,16,0)&"",VLOOKUP($A33,Questions!$A$2:$X$333,15,0)&"")) -> Provide additional information that may help analysts better understand your environment and how it relates to third-party solutions. | F33: =VLOOKUP($A33,'Institution Evaluation'!$A$56:$F$346,6,0)&""
A34: THRD-05 | B34: =VLOOKUP($A34,Questions!$A$2:$X$333,2,0) -> Do you have a process and implemented procedures for managing your hardware supply chain (e.g., telecommunications equipment, export licensing, computing devices)? | C34: Yes | D34: See our security overview for more information. | E34: =IF($C34="Yes",VLOOKUP($A34,Questions!$A$2:$X$333,17,0)&"",IF($C34="No",VLOOKUP($A34,Questions!$A$2:$X$333,16,0)&"",VLOOKUP($A34,Questions!$A$2:$X$333,15,0)&"")) -> State what countries and/or regions this process is compliant with. | F34: =VLOOKUP($A34,'Institution Evaluation'!$A$56:$F$346,6,0)&"" | G34: End Table Data
A35: =VLOOKUP(LEFT($A36,4),'Auto Responses'!$N$4:$O$38,2,0)&"" -> Change Management | C35: Answer | D35: Additional Information | E35: Guidance | F35: Analyst Notes
A36: CHNG-01 | B36: =VLOOKUP($A36,Questions!$A$2:$X$333,2,0) -> Will the institution be notified of major changes to your environment that could impact the institution's security posture?* | C36: Yes | D36: Institutions will be notified within 24 hours | E36: =IF($C36="Yes",VLOOKUP($A36,Questions!$A$2:$X$333,17,0)&"",IF($C36="No",VLOOKUP($A36,Questions!$A$2:$X$333,16,0)&"",VLOOKUP($A36,Questions!$A$2:$X$333,15,0)&"")) -> State how and when the institution will be notified of major changes to your environment. | F36: =VLOOKUP($A36,'Institution Evaluation'!$A$56:$F$346,6,0)&""
A37: CHNG-02 | B37: =VLOOKUP($A37,Questions!$A$2:$X$333,2,0) -> Does the system support client customizations from one release to another?* | C37: Yes | D37: Coursedog is a software as a service (SaaS) solution and therefore all usrs operate within the same version. See answer to CHNG-04 for more details on feature specific items. | E37: =IF($C37="Yes",VLOOKUP($A37,Questions!$A$2:$X$333,17,0)&"",IF($C37="No",VLOOKUP($A37,Questions!$A$2:$X$333,16,0)&"",VLOOKUP($A37,Questions!$A$2:$X$333,15,0)&"")) -> Describe or provide reference to your solution support strategy in regard to maintaining client customizations from one release to another. | F37: =VLOOKUP($A37,'Institution Evaluation'!$A$56:$F$346,6,0)&""
A38: CHNG-03 | B38: =VLOOKUP($A38,Questions!$A$2:$X$333,2,0) -> Do you have an implemented system configuration management process (e.g.,secure "gold" images, etc.)?* | C38: Yes | D38: AWS | E38: =IF($C38="Yes",VLOOKUP($A38,Questions!$A$2:$X$333,17,0)&"",IF($C38="No",VLOOKUP($A38,Questions!$A$2:$X$333,16,0)&"",VLOOKUP($A38,Questions!$A$2:$X$333,15,0)&"")) -> Summarize your implemented system configuration management precess. | F38: =VLOOKUP($A38,'Institution Evaluation'!$A$56:$F$346,6,0)&""
A39: CHNG-04 | B39: =VLOOKUP($A39,Questions!$A$2:$X$333,2,0) -> Do you have a documented change management process? | C39: Yes | D39: Coursedog communicates all platform wide updates. (See release notes) All features (e.g. integration changes) are behind a feature toggle and therefore can opted out. Coursedog recommends you disucuss specific situations with your dedicated Customer Success Manager (CSM). | E39: =IF($C39="Yes",VLOOKUP($A39,Questions!$A$2:$X$333,17,0)&"",IF($C39="No",VLOOKUP($A39,Questions!$A$2:$X$333,16,0)&"",VLOOKUP($A39,Questions!$A$2:$X$333,15,0)&"")) -> Summarize your current change management process. | F39: =VLOOKUP($A39,'Institution Evaluation'!$A$56:$F$346,6,0)&""
A40: CHNG-05 | B40: =VLOOKUP($A40,Questions!$A$2:$X$333,2,0) -> Does your change management process minimally include authorization, impact analysis, testing, and validation before moving changes to production? | C40: Yes | D40: Our change management process includes impact analysis, authorization by leadership, testing in staging, and validation before moving to production. Learn More about Change Management | E40: =IF($C40="Yes",VLOOKUP($A40,Questions!$A$2:$X$333,17,0)&"",IF($C40="No",VLOOKUP($A40,Questions!$A$2:$X$333,16,0)&"",VLOOKUP($A40,Questions!$A$2:$X$333,15,0)&"")) -> Indicate all procedures that are implemented in your change management process. (a) An impact analysis of the upgrade is performed. (b) The change is appropriately authorized. (c) Changes are made first in a test environment. (d) The ability to implement the upgrades/changes in the production environment is limited to appropriate IT personnel. | F40: =VLOOKUP($A40,'Institution Evaluation'!$A$56:$F$346,6,0)&""
...

Sheet Product
A1: Cells contained in this worksheet may contain cells with dropdown lists as well as autopopulated formulas.
A2: HECVAT Solution Provider Response - Product | F2: ='Auto Responses'!$A$36 -> Version 4.04
A3: Date Completed | C3: ='START HERE'!$C$3 -> 45933
A4: Instructions for Solution Providers
A5: =HLOOKUP($A$4,'Auto Responses'!$D$2:$D$8,2,0)&"" -> 1. Complete the "Start Here" tab and review the "Required Questions" guidance to find the other sections are required for your product or service.
A6: =HLOOKUP($A$4,'Auto Responses'!$D$2:$D$8,3,0)&"" -> 2. Complete the "Organization" tab and the applicable questions in each of the next 5 tabs (Product through Privacy) that apply, based on your answers to the "Required Questions."
A7: =HLOOKUP($A$4,'Auto Responses'!$D$2:$D$8,4,0)&"" -> 3. Guidance in column E may change based on your answers to prompt details in "Additional Information." If leaving an answer blank, you must also state why in "Additional Information".
A8: =HLOOKUP($A$4,'Auto Responses'!$D$2:$D$8,5,0)&"" -> 4. DO NOT complete any fields in the "Evaluation" sheets or the "Analyst Notes" column.
A9: =HLOOKUP($A$4,'Auto Responses'!$D$2:$D$8,6,0)&"" -> 5. Return the completed file to institutions.
A10: =HLOOKUP($A$4,'Auto Responses'!$D$2:$D$8,7,0)&"" -> * Denotes critical questions. Critical questions are those deemed most important to institutions by higher education volunteers.
A11: =HLOOKUP($A$4,'Auto Responses'!$D$2:$D$9,8,0)&"" -> For full instructions, please visit educause.edu/HECVAT
A12: =VLOOKUP(LEFT($A13,4),'Auto Responses'!$N$4:$O$38,2,0)&"" -> General Information | C12: Answer
A13: GNRL-01 | B13: =VLOOKUP($A13,Questions!$A$2:$X$333,2,0)&"" -> Solution Provider Name | C13: =VLOOKUP($A13,'START HERE'!$A$13:$C$21,3,0)&"" -> Coursedog
A14: GNRL-02 | B14: =VLOOKUP($A14,Questions!$A$2:$X$333,2,0)&"" -> Solution Name | C14: =VLOOKUP($A14,'START HERE'!$A$13:$C$21,3,0)&"" -> Coursedog
A15: GNRL-03 | B15: =VLOOKUP($A15,Questions!$A$2:$X$333,2,0)&"" -> Solution Description | C15: =VLOOKUP($A15,'START HERE'!$A$13:$C$21,3,0)&"" -> Coursedog is a SaaS platform designed to streamline curriculum, catalog, and scheduling management for higher education institutions, offering intuitive tools, insightful analytics, and seamless integration without requiring IT involvement.
A16: GNRL-08 | B16: =VLOOKUP($A16,Questions!$A$2:$X$333,2,0)&"" -> Country of Company Headquarters | C16: =VLOOKUP($A16,'START HERE'!$A$13:$C$21,3,0)&"" -> United States
A17: =VLOOKUP(LEFT($A18,4),'Auto Responses'!$N$4:$O$38,2,0)&"" -> Required Questions | C17: Answer | E17: Guidance | F17: Analyst Notes
A18: REQU-01 | B18: =VLOOKUP($A18,Questions!$A$2:$X$333,2,0) -> Are you offering either a product or platform, as opposed to only offering a service | C18: =VLOOKUP($A18,'START HERE'!$A$23:$F$36,3,0)&"" -> Yes | D18: =VLOOKUP($A18,'START HERE'!$A$23:$F$36,4,0)&"" -> Coursedog is a SaaS platform designed to streamline curriculum, catalog, and scheduling management for higher education institutions, offering intuitive tools, insightful analytics, and seamless integration without requiring IT involvement. | E18: =IF($C18="Yes",VLOOKUP($A18,Questions!$A$2:$X$333,17,0)&"",IF($C18="No",VLOOKUP($A18,Questions!$A$2:$X$333,16,0)&"",VLOOKUP($A18,Questions!$A$2:$X$333,15,0)&"")) -> DO complete the Product and Infrastructure worksheets | F18: =VLOOKUP($A18,'Institution Evaluation'!$A$56:$F$346,6,0)&"" | G18: End Table Data
A19: =VLOOKUP(LEFT($A20,4),'Auto Responses'!$N$4:$O$38,2,0)&"" -> Authentication, Authorization, and Account Management | C19: Answer | D19: Additional Information | E19: Guidance | F19: Analyst Notes
A20: AAAI-01 | B20: =VLOOKUP($A20,Questions!$A$2:$X$333,2,0) -> Does your solution support single sign-on (SSO) protocols for user and administrator authentication?* | C20: Yes | D20: Yes, Coursedog supports SSO for authentication and provisioning purposes. Read More about SSO | E20: =IF($C$18="No",'Auto Responses'!$A$3,IF($C20="Yes",VLOOKUP($A20,Questions!$A$2:$X$333,17,0)&"",IF($C20="No",VLOOKUP($A20,Questions!$A$2:$X$333,16,0)&"",VLOOKUP($A20,Questions!$A$2:$X$333,15,0)&""))) -> Describe how strong authentication is enforced (e.g., complex passwords, multifactor tokens, certificates, biometrics, aging requirements, re-use policy). | F20: =VLOOKUP($A20,'Institution Evaluation'!$A$56:$F$346,6,0)&""
A21: AAAI-02 | B21: =VLOOKUP($A21,Questions!$A$2:$X$333,2,0) -> Does your solution support local authentication protocols for user and administrator authentication?* | C21: Yes | D21: See user Authentification documentation for more information. | E21: =IF($C$18="No",'Auto Responses'!$A$3,IF($C21="Yes",VLOOKUP($A21,Questions!$A$2:$X$333,17,0)&"",IF($C21="No",VLOOKUP($A21,Questions!$A$2:$X$333,16,0)&"",VLOOKUP($A21,Questions!$A$2:$X$333,15,0)&""))) -> Provide a detailed description of your local authentication mode practices. | F21: =VLOOKUP($A21,'Institution Evaluation'!$A$56:$F$346,6,0)&""
A22: AAAI-03 | B22: =VLOOKUP($A22,Questions!$A$2:$X$333,2,0) -> Can you enforce password/passphrase complexity requirements (provided by the institution)?* | C22: Yes | D22: Coursedog recommends you use single sign on (SSO) for all admin access to Coursedog. That said, Coursedog has password aging on our near term roadmap. | E22: =IF($C$18="No",'Auto Responses'!$A$3,IF($C22="Yes",VLOOKUP($A22,Questions!$A$2:$X$333,17,0)&"",IF($C22="No",VLOOKUP($A22,Questions!$A$2:$X$333,16,0)&"",VLOOKUP($A22,Questions!$A$2:$X$333,15,0)&""))) -> Describe how password/passphrase complexity requirements are implemented in the product. | F22: =VLOOKUP($A22,'Institution Evaluation'!$A$56:$F$346,6,0)&""
A23: AAAI-04 | B23: =VLOOKUP($A23,Questions!$A$2:$X$333,2,0) -> Does the system have password complexity or length limitations and/or restrictions?* | C23: Yes | D23: Coursedog recommends you use single sign on (SSO) for all admin access to Coursedog. That said, Coursedog has password aging on our near term roadmap. | E23: =IF($C$18="No",'Auto Responses'!$A$3,IF($C23="Yes",VLOOKUP($A23,Questions!$A$2:$X$333,17,0)&"",IF($C23="No",VLOOKUP($A23,Questions!$A$2:$X$333,16,0)&"",VLOOKUP($A23,Questions!$A$2:$X$333,15,0)&""))) -> Describe these limitations and/or restrictions and state what lengths and complexities are supported. | F23: =VLOOKUP($A23,'Institution Evaluation'!$A$56:$F$346,6,0)&""
A24: AAAI-05 | B24: =VLOOKUP($A24,Questions!$A$2:$X$333,2,0) -> Do you have documented password/passphrase reset procedures that are currently implemented in the system and/or customer support?* | C24: Yes | D24: Coursedog reccomends using Single Sign On (SSO) for authentication. However, users can reset their passwords by following the steps on the sign-in page or through "Account Settings" if they know their current password. Read More about Resetting Passwords | E24: =IF($C$18="No",'Auto Responses'!$A$3,IF($C24="Yes",VLOOKUP($A24,Questions!$A$2:$X$333,17,0)&"",IF($C24="No",VLOOKUP($A24,Questions!$A$2:$X$333,16,0)&"",VLOOKUP($A24,Questions!$A$2:$X$333,15,0)&""))) -> Describe your documented password/passphrase reset procedures that are currently implemented in the system and/or customer support. | F24: =VLOOKUP($A24,'Institution Evaluation'!$A$56:$F$346,6,0)&""
A25: AAAI-06 | B25: =VLOOKUP($A25,Questions!$A$2:$X$333,2,0) -> Does your organization participate in InCommon or another eduGAIN-affiliated trust federation?* | C25: Yes | D25: Coursedog supports SAML and CAS for single sign on (SSO) | E25: =IF($C$18="No",'Auto Responses'!$A$3,IF($C25="Yes",VLOOKUP($A25,Questions!$A$2:$X$333,17,0)&"",IF($C25="No",VLOOKUP($A25,Questions!$A$2:$X$333,16,0)&"",VLOOKUP($A25,Questions!$A$2:$X$333,15,0)&""))) -> List the entity IDs registered in the Additional Information column. | F25: =VLOOKUP($A25,'Institution Evaluation'!$A$56:$F$346,6,0)&""
A26: AAAI-07 | B26: =VLOOKUP($A26,Questions!$A$2:$X$333,2,0) -> Are there any passwords/passphrases hard-coded into your systems or solutions?* | C26: No | E26: =IF($C$18="No",'Auto Responses'!$A$3,IF($C26="Yes",VLOOKUP($A26,Questions!$A$2:$X$333,17,0)&"",IF($C26="No",VLOOKUP($A26,Questions!$A$2:$X$333,16,0)&"",VLOOKUP($A26,Questions!$A$2:$X$333,15,0)&""))) | F26: =VLOOKUP($A26,'Institution Evaluation'!$A$56:$F$346,6,0)&""
A27: AAAI-08 | B27: =VLOOKUP($A27,Questions!$A$2:$X$333,2,0) -> Are you storing any passwords in plaintext?* | C27: No | E27: =IF($C$18="No",'Auto Responses'!$A$3,IF($C27="Yes",VLOOKUP($A27,Questions!$A$2:$X$333,17,0)&"",IF($C27="No",VLOOKUP($A27,Questions!$A$2:$X$333,16,0)&"",VLOOKUP($A27,Questions!$A$2:$X$333,15,0)&""))) | F27: =VLOOKUP($A27,'Institution Evaluation'!$A$56:$F$346,6,0)&""
A28: AAAI-09 | B28: =VLOOKUP($A28,Questions!$A$2:$X$333,2,0) -> Are audit logs available that include AT LEAST all of the following: login, logout, actions performed, and source IP address?* | C28: Yes | D28: All user activity is logged. Most of the activity accessible in our admin panel by select administrators (see RBAC answer). | E28: =IF($C$18="No",'Auto Responses'!$A$3,IF($C28="Yes",VLOOKUP($A28,Questions!$A$2:$X$333,17,0)&"",IF($C28="No",VLOOKUP($A28,Questions!$A$2:$X$333,16,0)&"",VLOOKUP($A28,Questions!$A$2:$X$333,15,0)&""))) | F28: =VLOOKUP($A28,'Institution Evaluation'!$A$56:$F$346,6,0)&""
A29: AAAI-10 | B29: =VLOOKUP($A29,Questions!$A$2:$X$333,2,0) -> Describe or provide a reference to the (a) system capability to log security/authorization changes, as well as user and administrator security events (i.e., physical or electronic), such as login failures, access denied, changes accepted; and (b) all requirements necessary to implement logging and monitoring on the system. Include (c) information about SIEM/log collector usage.* | C29: All logs for security changes and user security are implemented and stored via AWS: https://docs.aws.amazon.com/elasticloadbalancing/latest/classic/access-log-collection.html https://docs.aws.amazon.com/organizations/latest/userguide/orgs_monitoring.html#orgs_cloudtrail-integration | E29: =IF($C$18="No",'Auto Responses'!$A$3,IF($C29="Yes",VLOOKUP($A29,Questions!$A$2:$X$333,17,0)&"",IF($C29="No",VLOOKUP($A29,Questions!$A$2:$X$333,16,0)&"",VLOOKUP($A29,Questions!$A$2:$X$333,15,0)&""))) -> Ensure that all elements of AAAI-10 are clearly stated in your response. | F29: =VLOOKUP($A29,'Institution Evaluation'!$A$56:$F$346,6,0)&""
A30: AAAI-11 | B30: =VLOOKUP($A30,Questions!$A$2:$X$333,2,0) -> Can you provide the institution documentation regarding the retention period for those logs, how logs are protected, and whether they are accessible to the customer (and if so, how)?* | C30: Yes | D30: Coursedog maintains Activity Logs indefinitely. | E30: =IF($C$18="No",'Auto Responses'!$A$3,IF($C30="Yes",VLOOKUP($A30,Questions!$A$2:$X$333,17,0)&"",IF($C30="No",VLOOKUP($A30,Questions!$A$2:$X$333,16,0)&"",VLOOKUP($A30,Questions!$A$2:$X$333,15,0)&""))) | F30: =VLOOKUP($A30,'Institution Evaluation'!$A$56:$F$346,6,0)&""
A31: AAAI-12 | B31: =VLOOKUP($A31,Questions!$A$2:$X$333,2,0) -> Does your application support integration with other authentication and authorization systems? | C31: Yes | D31: Coursedog supports Active Directory though single sign on (SSO) | E31: =IF($C$18="No",'Auto Responses'!$A$3,IF($C31="Yes",VLOOKUP($A31,Questions!$A$2:$X$333,17,0)&"",IF($C31="No",VLOOKUP($A31,Questions!$A$2:$X$333,16,0)&"",VLOOKUP($A31,Questions!$A$2:$X$333,15,0)&""))) -> List which systems and versions supported (such as Active Directory, Kerberos, or other LDAP compatible directory) in Additional Info. | F31: =VLOOKUP($A31,'Institution Evaluation'!$A$56:$F$346,6,0)&""
A32: AAAI-13 | B32: =VLOOKUP($A32,Questions!$A$2:$X$333,2,0) -> Do you allow the customer to specify attribute mappings for any needed information beyond a user identifier? (e.g., Reference eduPerson, ePPA/ePPN/ePE) | C32: Yes | E32: =IF($C$18="No",'Auto Responses'!$A$3,IF($C32="Yes",VLOOKUP($A32,Questions!$A$2:$X$333,17,0)&"",IF($C32="No",VLOOKUP($A32,Questions!$A$2:$X$333,16,0)&"",VLOOKUP($A32,Questions!$A$2:$X$333,15,0)&""))) | F32: =VLOOKUP($A32,'Institution Evaluation'!$A$56:$F$346,6,0)&""
A33: AAAI-14 | B33: =VLOOKUP($A33,Questions!$A$2:$X$333,2,0) -> Does your application support directory integration for user accounts? | C33: Yes | D33: Coursedog supports user creation and role assignments via SSO, which can be integrated with directory services. Learn More about SSO Integration | E33: =IF($C$18="No",'Auto Responses'!$A$3,IF($C33="Yes",VLOOKUP($A33,Questions!$A$2:$X$333,17,0)&"",IF($C33="No",VLOOKUP($A33,Questions!$A$2:$X$333,16,0)&"",VLOOKUP($A33,Questions!$A$2:$X$333,15,0)&""))) -> Describe all authentication services supported by the system. | F33: =VLOOKUP($A33,'Institution Evaluation'!$A$56:$F$346,6,0)&""
A34: AAAI-15 | B34: =VLOOKUP($A34,Questions!$A$2:$X$333,2,0) -> Does your solution support any of the following web SSO standards: SAML2 (with redirect flow), OIDC, CAS, or other? | C34: Yes | D34: Coursedog supports SAML and CAS for single sign on (SSO) | E34: =IF($C$18="No",'Auto Responses'!$A$3,IF($C34="Yes",VLOOKUP($A34,Questions!$A$2:$X$333,17,0)&"",IF($C34="No",VLOOKUP($A34,Questions!$A$2:$X$333,16,0)&"",VLOOKUP($A34,Questions!$A$2:$X$333,15,0)&""))) -> State the web SSO standards supported by your solution and provide additional details about your support, including framework(s) in use, how information is exchanged securely, etc. | F34: =VLOOKUP($A34,'Institution Evaluation'!$A$56:$F$346,6,0)&""
A35: AAAI-16 | B35: =VLOOKUP($A35,Questions!$A$2:$X$333,2,0) -> Do you support differentiation between email address and user identifier? | C35: Yes | E35: =IF($C$18="No",'Auto Responses'!$A$3,IF($C35="Yes",VLOOKUP($A35,Questions!$A$2:$X$333,17,0)&"",IF($C35="No",VLOOKUP($A35,Questions!$A$2:$X$333,16,0)&"",VLOOKUP($A35,Questions!$A$2:$X$333,15,0)&""))) | F35: =VLOOKUP($A35,'Institution Evaluation'!$A$56:$F$346,6,0)&""
A36: AAAI-17 | B36: =VLOOKUP($A36,Questions!$A$2:$X$333,2,0) -> If the institution does not use SSO, does your application and/or user frontend/portal support multifactor authentication (e.g., Duo, Google Authenticator, OTP, etc.)? | C36: No | D36: Coursedog recommends you use single sign on (SSO) to leverage any 2FA at your institution for all admin access to Coursedog. | E36: =IF($C$18="No",'Auto Responses'!$A$3,IF($C$20="No",'Auto Responses'!$A$28,IF($C36="Yes",VLOOKUP($A36,Questions!$A$2:$X$333,17,0)&"",IF($C36="No",VLOOKUP($A36,Questions!$A$2:$X$333,16,0)&"",VLOOKUP($A36,Questions!$A$2:$X$333,15,0)&"")))) -> Describe any plans to support multifactor authentication in your application. | F36: =VLOOKUP($A36,'Institution Evaluation'!$A$56:$F$346,6,0)&""
A37: AAAI-18 | B37: =VLOOKUP($A37,Questions!$A$2:$X$333,2,0) -> Does your application automatically lock the session or log out an account after a period of inactivity? | C37: Yes | D37: If you are inactive for more than 24 hours, you will automatically be logged out of Coursedog. Read More about Logging Out | E37: =IF($C$18="No",'Auto Responses'!$A$3,IF($C37="Yes",VLOOKUP($A37,Questions!$A$2:$X$333,17,0)&"",IF($C37="No",VLOOKUP($A37,Questions!$A$2:$X$333,16,0)&"",VLOOKUP($A37,Questions!$A$2:$X$333,15,0)&""))) -> Describe the default behavior of this capability. | F37: =VLOOKUP($A37,'Institution Evaluation'!$A$56:$F$346,6,0)&"" | G37: End Table Data
A38: =VLOOKUP(LEFT($A39,4),'Auto Responses'!$N$4:$O$38,2,0)&"" -> Data | C38: Answer | D38: Additional Information | E38: Guidance | F38: Analyst Notes
A39: DATA-01 | B39: =VLOOKUP($A39,Questions!$A$2:$X$333,2,0) -> Will the institution's data be stored on any devices (database servers, file servers, SAN, NAS, etc.) configured with non-RFC 1918/4193 (i.e., publicly routable) IP addresses?* | C39: No | E39: =IF($C$18="No",'Auto Responses'!$A$3,IF($C39="Yes",VLOOKUP($A39,Questions!$A$2:$X$333,17,0)&"",IF($C39="No",VLOOKUP($A39,Questions!$A$2:$X$333,16,0)&"",VLOOKUP($A39,Questions!$A$2:$X$333,15,0)&""))) | F39: =VLOOKUP($A39,'Institution Evaluation'!$A$56:$F$346,6,0)&""
A40: DATA-02 | B40: =VLOOKUP($A40,Questions!$A$2:$X$333,2,0) -> Is the transport of sensitive data encrypted using security protocols/algorithms (e.g., system-to-client)?* | C40: Yes | D40: See our security overview for more information. | E40: =IF($C$18="No",'Auto Responses'!$A$3,IF($C40="Yes",VLOOKUP($A40,Questions!$A$2:$X$333,17,0)&"",IF($C40="No",VLOOKUP($A40,Questions!$A$2:$X$333,16,0)&"",VLOOKUP($A40,Questions!$A$2:$X$333,15,0)&""))) -> Summarize your transport encryption strategy. | F40: =VLOOKUP($A40,'Institution Evaluation'!$A$56:$F$346,6,0)&""
...

Sheet Infrastructure
A1: Cells contained in this worksheet may contain cells with dropdown lists as well as autopopulated formulas.
A2: HECVAT Solution Provider Response - Infrastructure | F2: ='Auto Responses'!$A$36 -> Version 4.04
A3: Date Completed | C3: ='START HERE'!$C$3 -> 45933
A4: Instructions for Solution Providers
A5: =HLOOKUP($A$4,'Auto Responses'!$D$2:$D$8,2,0)&"" -> 1. Complete the "Start Here" tab and review the "Required Questions" guidance to find the other sections are required for your product or service.
A6: =HLOOKUP($A$4,'Auto Responses'!$D$2:$D$8,3,0)&"" -> 2. Complete the "Organization" tab and the applicable questions in each of the next 5 tabs (Product through Privacy) that apply, based on your answers to the "Required Questions."
A7: =HLOOKUP($A$4,'Auto Responses'!$D$2:$D$8,4,0)&"" -> 3. Guidance in column E may change based on your answers to prompt details in "Additional Information." If leaving an answer blank, you must also state why in "Additional Information".
A8: =HLOOKUP($A$4,'Auto Responses'!$D$2:$D$8,5,0)&"" -> 4. DO NOT complete any fields in the "Evaluation" sheets or the "Analyst Notes" column.
A9: =HLOOKUP($A$4,'Auto Responses'!$D$2:$D$8,6,0)&"" -> 5. Return the completed file to institutions.
A10: =HLOOKUP($A$4,'Auto Responses'!$D$2:$D$8,7,0)&"" -> * Denotes critical questions. Critical questions are those deemed most important to institutions by higher education volunteers.
A11: =HLOOKUP($A$4,'Auto Responses'!$D$2:$D$9,8,0)&"" -> For full instructions, please visit educause.edu/HECVAT
A12: =VLOOKUP(LEFT($A13,4),'Auto Responses'!$N$4:$O$38,2,0)&"" -> General Information | C12: Answer
A13: GNRL-01 | B13: =VLOOKUP($A13,Questions!$A$2:$X$333,2,0)&"" -> Solution Provider Name | C13: =VLOOKUP($A13,'START HERE'!$A$13:$C$21,3,0)&"" -> Coursedog
A14: GNRL-02 | B14: =VLOOKUP($A14,Questions!$A$2:$X$333,2,0)&"" -> Solution Name | C14: =VLOOKUP($A14,'START HERE'!$A$13:$C$21,3,0)&"" -> Coursedog
A15: GNRL-03 | B15: =VLOOKUP($A15,Questions!$A$2:$X$333,2,0)&"" -> Solution Description | C15: =VLOOKUP($A15,'START HERE'!$A$13:$C$21,3,0)&"" -> Coursedog is a SaaS platform designed to streamline curriculum, catalog, and scheduling management for higher education institutions, offering intuitive tools, insightful analytics, and seamless integration without requiring IT involvement.
A16: GNRL-08 | B16: =VLOOKUP($A16,Questions!$A$2:$X$333,2,0)&"" -> Country of Company Headquarters | C16: =VLOOKUP($A16,'START HERE'!$A$13:$C$21,3,0)&"" -> United States
A17: =VLOOKUP(LEFT($A18,4),'Auto Responses'!$N$4:$O$38,2,0)&"" -> Required Questions | C17: Answer | E17: Guidance | F17: Analyst Notes
A18: REQU-01 | B18: =VLOOKUP($A18,Questions!$A$2:$X$333,2,0) -> Are you offering either a product or platform, as opposed to only offering a service | C18: =VLOOKUP($A18,'START HERE'!$A$23:$F$36,3,0)&"" -> Yes | D18: =VLOOKUP($A18,'START HERE'!$A$23:$F$36,4,0)&"" -> Coursedog is a SaaS platform designed to streamline curriculum, catalog, and scheduling management for higher education institutions, offering intuitive tools, insightful analytics, and seamless integration without requiring IT involvement. | E18: =IF($C18="Yes",VLOOKUP($A18,Questions!$A$2:$X$333,17,0)&"",IF($C18="No",VLOOKUP($A18,Questions!$A$2:$X$333,16,0)&"",VLOOKUP($A18,Questions!$A$2:$X$333,15,0)&"")) -> DO complete the Product and Infrastructure worksheets | F18: =VLOOKUP($A18,'Institution Evaluation'!$A$56:$F$346,6,0)&"" | G18: End Table Data
A19: =VLOOKUP(LEFT($A20,4),'Auto Responses'!$N$4:$O$38,2,0)&"" -> Application/Service Security | C19: Answer | D19: Additional Information | E19: Guidance | F19: Analyst Notes
A20: APPL-01 | B20: =VLOOKUP($A20,Questions!$A$2:$X$333,2,0) -> Are access controls for institutional accounts based on structured rules, such as role-based access control (RBAC), attribute-based access control (ABAC), or policy-based access control (PBAC)?* | C20: Yes | D20: Coursedog supports role-based access control (RBAC). You can create, manage, and remove permissions for various roles. Products come pre-loaded with a set of roles, but you can also create custom roles and set different permissions for each role. Permissions can be set on a product-wide level, with additional role-based permissions available on the field-level. | E20: =IF($C$18="No",'Auto Responses'!$A$3,IF($C20="Yes",VLOOKUP($A20,Questions!$A$2:$X$333,17,0)&"",IF($C20="No",VLOOKUP($A20,Questions!$A$2:$X$333,16,0)&"",VLOOKUP($A20,Questions!$A$2:$X$333,15,0)&""))) -> Describe available roles. | F20: =VLOOKUP($A20,'Institution Evaluation'!$A$56:$F$346,6,0)&""
A21: APPL-02 | B21: =VLOOKUP($A21,Questions!$A$2:$X$333,2,0) -> Are you using a web application firewall (WAF)?* | C21: Yes | D21: See AWS firewall documentation | E21: =IF($C$18="No",'Auto Responses'!$A$3,IF($C21="Yes",VLOOKUP($A21,Questions!$A$2:$X$333,17,0)&"",IF($C21="No",VLOOKUP($A21,Questions!$A$2:$X$333,16,0)&"",VLOOKUP($A21,Questions!$A$2:$X$333,15,0)&""))) -> Describe the currently implemented WAF. | F21: =VLOOKUP($A21,'Institution Evaluation'!$A$56:$F$346,6,0)&""
A22: APPL-03 | B22: =VLOOKUP($A22,Questions!$A$2:$X$333,2,0) -> Are only currently supported operating system(s), software, and libraries leveraged by the system(s)/application(s) that will have access to institution's data?* | C22: Yes | D22: See Coursedog application and infastructure archutecture documents | F22: =VLOOKUP($A22,'Institution Evaluation'!$A$56:$F$346,6,0)&""
A23: APPL-04 | B23: =VLOOKUP($A23,Questions!$A$2:$X$333,2,0) -> Does your application require access to location or GPS data? | C23: No | D23: Can be leveraged but not required. See our support article for more information | E23: =IF($C$18="No",'Auto Responses'!$A$3,IF($C23="Yes",VLOOKUP($A23,Questions!$A$2:$X$333,17,0)&"",IF($C23="No",VLOOKUP($A23,Questions!$A$2:$X$333,16,0)&"",VLOOKUP($A23,Questions!$A$2:$X$333,15,0)&""))) -> Please indicate any future plans that would require access to this data | F23: =VLOOKUP($A23,'Institution Evaluation'!$A$56:$F$346,6,0)&""
A24: APPL-05 | B24: =VLOOKUP($A24,Questions!$A$2:$X$333,2,0) -> Does your application provide separation of duties between security administration, system administration, and standard user functions?* | C24: Yes | D24: https://aws.amazon.com/security/ | F24: =VLOOKUP($A24,'Institution Evaluation'!$A$56:$F$346,6,0)&""
A25: APPL-06 | B25: =VLOOKUP($A25,Questions!$A$2:$X$333,2,0) -> Do you subject your code to static code analysis and/or static application security testing prior to release?* | C25: Yes | D25: Eslint | E25: =IF($C$18="No",'Auto Responses'!$A$3,IF($C25="Yes",VLOOKUP($A25,Questions!$A$2:$X$333,17,0)&"",IF($C25="No",VLOOKUP($A25,Questions!$A$2:$X$333,16,0)&"",VLOOKUP($A25,Questions!$A$2:$X$333,15,0)&""))) -> Provide a list of all tools utilized during static code analysis or static application security testing. | F25: =VLOOKUP($A25,'Institution Evaluation'!$A$56:$F$346,6,0)&""
A26: APPL-07 | B26: =VLOOKUP($A26,Questions!$A$2:$X$333,2,0) -> Do you have software testing processes (dynamic or static) that are established and followed?* | C26: Yes | D26: Coursedog practices a two week agile development process with test driven deployment (TDD). Developers build the specification to the test and push changes to a QA system where it is thoroughly tested. Updates are then moved to a staging environment where they can be tested by active implementations before they are pushed to production, where they are gated behind role based access control and admins can opt into using the functionality. We provide change logs to end users and admins when new functionality is deployed. Any end user is able to provide feedback through our public bug tracking tool if a bug is found in the production. | E26: =IF($C$18="No",'Auto Responses'!$A$3,IF($C26="Yes",VLOOKUP($A26,Questions!$A$2:$X$333,17,0)&"",IF($C26="No",VLOOKUP($A26,Questions!$A$2:$X$333,16,0)&"",VLOOKUP($A26,Questions!$A$2:$X$333,15,0)&""))) -> Describe testing processes, including but not limited to, development of test plans, personnel involved in the testing process, and authorized individual accountable for approval and certification of test results. | F26: =VLOOKUP($A26,'Institution Evaluation'!$A$56:$F$346,6,0)&""
A27: APPL-08 | B27: =VLOOKUP($A27,Questions!$A$2:$X$333,2,0) -> Are access controls for staff within your organization based on structured rules, such as RBAC, ABAC, or PBAC? | C27: Yes | D27: Coursedog supports role-based access control (RBAC) for staff within the organization. You can create, manage, and remove permissions for various roles, allowing for structured access control based on roles. | E27: =IF($C$18="No",'Auto Responses'!$A$3,IF($C27="Yes",VLOOKUP($A27,Questions!$A$2:$X$333,17,0)&"",IF($C27="No",VLOOKUP($A27,Questions!$A$2:$X$333,16,0)&"",VLOOKUP($A27,Questions!$A$2:$X$333,15,0)&""))) | F27: =VLOOKUP($A27,'Institution Evaluation'!$A$56:$F$346,6,0)&""
A28: APPL-09 | B28: =VLOOKUP($A28,Questions!$A$2:$X$333,2,0) -> Does the system provide data input validation and error messages? | C28: Yes | D28: See our support article explaining our error handling in more detail. | E28: =IF($C$18="No",'Auto Responses'!$A$3,IF($C28="Yes",VLOOKUP($A28,Questions!$A$2:$X$333,17,0)&"",IF($C28="No",VLOOKUP($A28,Questions!$A$2:$X$333,16,0)&"",VLOOKUP($A28,Questions!$A$2:$X$333,15,0)&""))) -> Describe how your system(s) provide data input validation and error messages. | F28: =VLOOKUP($A28,'Institution Evaluation'!$A$56:$F$346,6,0)&""
A29: APPL-10 | B29: =VLOOKUP($A29,Questions!$A$2:$X$333,2,0) -> Do you have a process and implemented procedures for managing your software supply chain (e.g., libraries, repositories, frameworks, etc.) | C29: Yes | D29: See Coursedog - Configuration Management Policy | E29: =IF($C$18="No",'Auto Responses'!$A$3,IF($C29="Yes",VLOOKUP($A29,Questions!$A$2:$X$333,17,0)&"",IF($C29="No",VLOOKUP($A29,Questions!$A$2:$X$333,16,0)&"",VLOOKUP($A29,Questions!$A$2:$X$333,15,0)&""))) -> Provide supporting documentation of your processes. | F29: =VLOOKUP($A29,'Institution Evaluation'!$A$56:$F$346,6,0)&""
A30: APPL-11 | B30: =VLOOKUP($A30,Questions!$A$2:$X$333,2,0) -> Have your developers been trained in secure coding techniques? | C30: Yes | D30: See OWASP | E30: =IF($C$18="No",'Auto Responses'!$A$3,IF($C30="Yes",VLOOKUP($A30,Questions!$A$2:$X$333,17,0)&"",IF($C30="No",VLOOKUP($A30,Questions!$A$2:$X$333,16,0)&"",VLOOKUP($A30,Questions!$A$2:$X$333,15,0)&""))) -> Summarize your secure coding training. | F30: =VLOOKUP($A30,'Institution Evaluation'!$A$56:$F$346,6,0)&""
A31: APPL-12 | B31: =VLOOKUP($A31,Questions!$A$2:$X$333,2,0) -> Was your application developed using secure coding techniques? | C31: Yes | D31: See OWASP | E31: =IF($C$18="No",'Auto Responses'!$A$3,IF($C31="Yes",VLOOKUP($A31,Questions!$A$2:$X$333,17,0)&"",IF($C31="No",VLOOKUP($A31,Questions!$A$2:$X$333,16,0)&"",VLOOKUP($A31,Questions!$A$2:$X$333,15,0)&""))) -> Summarize your secure coding practices. | F31: =VLOOKUP($A31,'Institution Evaluation'!$A$56:$F$346,6,0)&""
A32: APPL-13 | B32: =VLOOKUP($A32,Questions!$A$2:$X$333,2,0) -> If mobile, is the application available from a trusted source (e.g., App Store, Google Play Store)? | C32: N/A | E32: =IF($C$18="No",'Auto Responses'!$A$3,IF($C32="Yes",VLOOKUP($A32,Questions!$A$2:$X$333,17,0)&"",IF($C32="No",VLOOKUP($A32,Questions!$A$2:$X$333,16,0)&"",VLOOKUP($A32,Questions!$A$2:$X$333,15,0)&""))) -> Select N/A if there is no mobile version of your app. | F32: =VLOOKUP($A32,'Institution Evaluation'!$A$56:$F$346,6,0)&""
A33: APPL-14 | B33: =VLOOKUP($A33,Questions!$A$2:$X$333,2,0) -> Do you have a fully implemented policy or procedure that details how your employees obtain administrator access to institutional instance of the application? | C33: Yes | D33: Access to the Admin Dashboard is limited to Coursedog users with administrator permissions and the internal Coursedog team. This ensures that only authorized personnel can manage settings such as Single Sign On (SSO), integration settings, and user activity monitoring. Read More about the Admin Dashboard | E33: =IF($C$18="No",'Auto Responses'!$A$3,IF($C33="Yes",VLOOKUP($A33,Questions!$A$2:$X$333,17,0)&"",IF($C33="No",VLOOKUP($A33,Questions!$A$2:$X$333,16,0)&"",VLOOKUP($A33,Questions!$A$2:$X$333,15,0)&""))) -> Describe or provide a reference that details how administrator access is handled (e.g., provisioning, principle of least privilege, deprovisioning, etc.). | F33: =VLOOKUP($A33,'Institution Evaluation'!$A$56:$F$346,6,0)&"" | G33: End Table Data
A34: =VLOOKUP(LEFT($A35,4),'Auto Responses'!$N$4:$O$38,2,0)&"" -> Datacenter | C34: Answer | D34: Additional Information | E34: Guidance | F34: Analyst Notes
A35: DCTR-01 | B35: =VLOOKUP($A35,Questions!$A$2:$X$333,2,0) -> Select your hosting option. | C35: AWS | E35: =IF(OR($C35="",$C35="Other"),VLOOKUP($A35,Questions!$A$2:$X$333,15,0),"")&"" | F35: =VLOOKUP($A35,'Institution Evaluation'!$A$56:$F$346,6,0)&""
A36: DCTR-02 | B36: =VLOOKUP($A36,Questions!$A$2:$X$333,2,0) -> Is a SOC 2 Type 2 report available for the hosting environment? | C36: Yes | D36: See AWS SOC documentation | E36: =IF($C$35="","",IF(OR($C$35='Auto Responses'!$J$20,$C$35='Auto Responses'!$J$21,$C$35='Auto Responses'!$J$22),'Auto Responses'!$A$26,IF($C36="Yes",VLOOKUP($A36,Questions!$A$2:$X$333,17,0)&"",IF($C36="No",VLOOKUP($A36,Questions!$A$2:$X$333,16,0)&"",VLOOKUP($A36,Questions!$A$2:$X$333,15,0)&"")))) -> Based on the response to DCTR-01, this question does not apply to this product or service. | F36: =VLOOKUP($A36,'Institution Evaluation'!$A$56:$F$346,6,0)&""
A37: DCTR-03 | B37: =VLOOKUP($A37,Questions!$A$2:$X$333,2,0) -> Are you generally able to accommodate storing each institution's data within its geographic region? | C37: Yes | D37: See AWS overview | E37: =IF($C$35="","",IF($C37="Yes",VLOOKUP($A37,Questions!$A$2:$X$333,17,0)&"",IF($C37="No",VLOOKUP($A37,Questions!$A$2:$X$333,16,0)&"",VLOOKUP($A37,Questions!$A$2:$X$333,15,0)&""))) | F37: =VLOOKUP($A37,'Institution Evaluation'!$A$56:$F$346,6,0)&""
A38: DCTR-04 | B38: =VLOOKUP($A38,Questions!$A$2:$X$333,2,0) -> Are the data centers staffed 24 hours a day, seven days a week (i.e., 24 x 7 x 365)? | C38: Yes | D38: See AWS Controls | E38: =IF($C$35="","",IF(OR($C$35='Auto Responses'!$J$20,$C$35='Auto Responses'!$J$21,$C$35='Auto Responses'!$J$22),'Auto Responses'!$A$26,IF($C38="Yes",VLOOKUP($A38,Questions!$A$2:$X$333,17,0)&"",IF($C38="No",VLOOKUP($A38,Questions!$A$2:$X$333,16,0)&"",VLOOKUP($A38,Questions!$A$2:$X$333,15,0)&"")))) -> Based on the response to DCTR-01, this question does not apply to this product or service. | F38: =VLOOKUP($A38,'Institution Evaluation'!$A$56:$F$346,6,0)&""
A39: DCTR-05 | B39: =VLOOKUP($A39,Questions!$A$2:$X$333,2,0) -> Are your servers separated from other companies via a physical barrier, such as a cage or hard walls? | C39: Yes | D39: See AWS overview | E39: =IF($C$35="","",IF(OR($C$35='Auto Responses'!$J$17,$C$35='Auto Responses'!$J$19,$C$35='Auto Responses'!$J$20,$C$35='Auto Responses'!$J$21,$C$35='Auto Responses'!$J$22),'Auto Responses'!$A$26,IF($C39="Yes",VLOOKUP($A39,Questions!$A$2:$X$333,17,0)&"",IF($C39="No",VLOOKUP($A39,Questions!$A$2:$X$333,16,0)&"",VLOOKUP($A39,Questions!$A$2:$X$333,15,0)&"")))) -> Based on the response to DCTR-01, this question does not apply to this product or service. | F39: =VLOOKUP($A39,'Institution Evaluation'!$A$56:$F$346,6,0)&""
A40: DCTR-06 | B40: =VLOOKUP($A40,Questions!$A$2:$X$333,2,0) -> Does a physical barrier fully enclose the physical space, preventing unauthorized physical contact with any of your devices?* | C40: Yes | D40: See AWS overview | E40: =IF($C$35="","",IF(OR($C$35='Auto Responses'!$J$19,$C$35='Auto Responses'!$J$20,$C$35='Auto Responses'!$J$21,$C$35='Auto Responses'!$J$22),'Auto Responses'!$A$26,IF($C40="Yes",VLOOKUP($A40,Questions!$A$2:$X$333,17,0)&"",IF($C40="No",VLOOKUP($A40,Questions!$A$2:$X$333,16,0)&"",VLOOKUP($A40,Questions!$A$2:$X$333,15,0)&"")))) -> Based on the response to DCTR-01, this question does not apply to this product or service. | F40: =VLOOKUP($A40,'Institution Evaluation'!$A$56:$F$346,6,0)&""
...

Sheet IT Accessibility
A1: Cells contained in this worksheet may contain cells with dropdown lists as well as autopopulated formulas.
A2: HECVAT Solution Provider Response - IT Accessibility | F2: ='Auto Responses'!$A$36 -> Version 4.04
A3: Date Completed | C3: ='START HERE'!$C$3 -> 45933
A4: Instructions for Solution Providers
A5: =HLOOKUP($A$4,'Auto Responses'!$D$2:$D$8,2,0)&"" -> 1. Complete the "Start Here" tab and review the "Required Questions" guidance to find the other sections are required for your product or service.
A6: =HLOOKUP($A$4,'Auto Responses'!$D$2:$D$8,3,0)&"" -> 2. Complete the "Organization" tab and the applicable questions in each of the next 5 tabs (Product through Privacy) that apply, based on your answers to the "Required Questions."
A7: =HLOOKUP($A$4,'Auto Responses'!$D$2:$D$8,4,0)&"" -> 3. Guidance in column E may change based on your answers to prompt details in "Additional Information." If leaving an answer blank, you must also state why in "Additional Information".
A8: =HLOOKUP($A$4,'Auto Responses'!$D$2:$D$8,5,0)&"" -> 4. DO NOT complete any fields in the "Evaluation" sheets or the "Analyst Notes" column.
A9: =HLOOKUP($A$4,'Auto Responses'!$D$2:$D$8,6,0)&"" -> 5. Return the completed file to institutions.
A10: =HLOOKUP($A$4,'Auto Responses'!$D$2:$D$8,7,0)&"" -> * Denotes critical questions. Critical questions are those deemed most important to institutions by higher education volunteers.
A11: =HLOOKUP($A$4,'Auto Responses'!$D$2:$D$9,8,0)&"" -> For full instructions, please visit educause.edu/HECVAT
A12: =VLOOKUP(LEFT($A13,4),'Auto Responses'!$N$4:$O$38,2,0)&"" -> General Information | C12: Answer
